<?xml version="1.0" ?>
<!-- =================================================================================== -->
<!-- |    This document was autogenerated by xacro from hackev.xacro                   | -->
<!-- |    EDITING THIS FILE BY HAND IS NOT RECOMMENDED                                 | -->
<!-- =================================================================================== -->
<robot name="hackev" xmlns:xacro="http://www.ros.org/wiki/xacro">
  <gazebo>
    <plugin filename="libgazebo_ros_control.so" name="gazebo_ros_control">
      <robotNamespace>/hackev</robotNamespace>
    </plugin>
  </gazebo>
  <link name="base_link">
    <visual>
      <geometry>
        <mesh filename="package://hackev_description/meshs/hackev_body.dae"/>
      </geometry>
    </visual>
    <collision>
      <geometry>
        <mesh filename="package://hackev_description/meshs/hackev_body.dae"/>
      </geometry>
    </collision>
    <inertial>
      <mass value="1.3"/>
      <inertia ixx="1.0" ixy="0.0" ixz="0.0" iyy="1.0" iyz="0.0" izz="1.0"/>
    </inertial>
  </link>
  <link name="odom"/>
  <joint name="dummy_joint" type="fixed">
    <parent link="odom"/>
    <child link="base_link"/>
  </joint>
  <link name="left_wheel">
    <visual>
      <origin rpy="0 0.0 0" xyz="0 0 0"/>
      <geometry>
        <mesh filename="package://hackev_description/meshs/hackev_wheel.dae"/>
      </geometry>
    </visual>
    <collision>
      <origin rpy="0 0.0 0" xyz="0 0 0"/>
      <geometry>
        <mesh filename="package://hackev_description/meshs/hackev_wheel.dae"/>
      </geometry>
    </collision>
    <inertial>
      <mass value="0.1"/>
      <inertia ixx="1.0" ixy="0.0" ixz="0.0" iyy="1.0" iyz="0.0" izz="1.0"/>
    </inertial>
  </link>
  <joint name="left_wheel_joint" type="continuous">
    <axis rpy="0 0 0" xyz="1 0 0"/>
    <parent link="base_link"/>
    <child link="left_wheel"/>
    <origin rpy="0 0 0" xyz="0.064 0.002875 -0.00231"/>
  </joint>
  <link name="right_wheel">
    <visual>
      <origin rpy="0 3.14159265359 0" xyz="0 0 0"/>
      <geometry>
        <mesh filename="package://hackev_description/meshs/hackev_wheel.dae"/>
      </geometry>
    </visual>
    <collision>
      <origin rpy="0 3.14159265359 0" xyz="0 0 0"/>
      <geometry>
        <mesh filename="package://hackev_description/meshs/hackev_wheel.dae"/>
      </geometry>
    </collision>
    <inertial>
      <mass value="0.1"/>
      <inertia ixx="1.0" ixy="0.0" ixz="0.0" iyy="1.0" iyz="0.0" izz="1.0"/>
    </inertial>
  </link>
  <joint name="right_wheel_joint" type="continuous">
    <axis rpy="0 0 0" xyz="1 0 0"/>
    <parent link="base_link"/>
    <child link="right_wheel"/>
    <origin rpy="0 0 0" xyz="-0.064 0.002875 -0.00231"/>
  </joint>
  <link name="arm">
    <visual>
      <geometry>
        <mesh filename="package://hackev_description/meshs/hackev_arm.dae"/>
      </geometry>
    </visual>
    <collision>
      <geometry>
        <mesh filename="package://hackev_description/meshs/hackev_arm.dae"/>
      </geometry>
    </collision>
    <inertial>
      <mass value="0.1"/>
      <inertia ixx="1.0" ixy="0.0" ixz="0.0" iyy="1.0" iyz="0.0" izz="1.0"/>
    </inertial>
  </link>
  <joint name="arm_joint" type="continuous">
    <axis rpy="0 0 0" xyz="1 0 0"/>
    <parent link="base_link"/>
    <child link="arm"/>
    <origin rpy="0 0 0" xyz="0 -0.02893 0.01283"/>
  </joint>
  <link name="color">
    <visual>
      <geometry>
        <mesh filename="package://hackev_description/meshs/hackev_color.dae"/>
      </geometry>
    </visual>
    <collision>
      <geometry>
        <mesh filename="package://hackev_description/meshs/hackev_color.dae"/>
      </geometry>
    </collision>
    <inertial>
      <mass value="0.05"/>
      <inertia ixx="1.0" ixy="0.0" ixz="0.0" iyy="1.0" iyz="0.0" izz="1.0"/>
    </inertial>
  </link>
  <joint name="color_joint" type="fixed">
    <parent link="arm"/>
    <child link="color"/>
    <origin rpy="0 0 0" xyz="0 -0.02995 -0.02625"/>
  </joint>
  <link name="tail">
    <visual>
      <geometry>
        <mesh filename="package://hackev_description/meshs/hackev_tail.dae"/>
      </geometry>
    </visual>
    <collision>
      <geometry>
        <mesh filename="package://hackev_description/meshs/hackev_tail.dae"/>
      </geometry>
    </collision>
    <inertial>
      <mass value="0.2"/>
      <inertia ixx="1.0" ixy="0.0" ixz="0.0" iyy="1.0" iyz="0.0" izz="1.0"/>
    </inertial>
  </link>
  <joint name="tail_joint" type="continuous">
    <axis rpy="0 0 0" xyz="0 1 0"/>
    <parent link="base_link"/>
    <child link="tail"/>
    <origin rpy="0.0785398 0 0" xyz="0 0.1517738 0.0114206"/>
  </joint>
  <link name="gyro">
    <visual>
      <geometry>
        <mesh filename="package://hackev_description/meshs/hackev_gyro.dae"/>
      </geometry>
    </visual>
    <collision>
      <geometry>
        <mesh filename="package://hackev_description/meshs/hackev_gyro.dae"/>
      </geometry>
    </collision>
    <inertial>
      <mass value="0.05"/>
      <inertia ixx="1.0" ixy="0.0" ixz="0.0" iyy="1.0" iyz="0.0" izz="1.0"/>
    </inertial>
  </link>
  <joint name="gyro_joint" type="fixed">
    <parent link="base_link"/>
    <child link="gyro"/>
    <origin rpy="0 0 0" xyz="-0.048 0.0318875 0.0773275"/>
  </joint>
  <link name="touch">
    <visual>
      <geometry>
        <mesh filename="package://hackev_description/meshs/hackev_touch.dae"/>
      </geometry>
    </visual>
    <collision>
      <geometry>
        <mesh filename="package://hackev_description/meshs/hackev_touch.dae"/>
      </geometry>
    </collision>
    <inertial>
      <mass value="0.05"/>
      <inertia ixx="1.0" ixy="0.0" ixz="0.0" iyy="1.0" iyz="0.0" izz="1.0"/>
    </inertial>
  </link>
  <joint name="touch_joint" type="fixed">
    <parent link="base_link"/>
    <child link="touch"/>
    <origin rpy="0 0 0" xyz="0.048 0.0318875 0.0773275"/>
  </joint>
  <link name="ultrasonic">
    <visual>
      <geometry>
        <mesh filename="package://hackev_description/meshs/hackev_ultrasonic.dae"/>
      </geometry>
    </visual>
    <collision>
      <geometry>
        <mesh filename="package://hackev_description/meshs/hackev_ultrasonic.dae"/>
      </geometry>
    </collision>
    <inertial>
      <mass value="0.05"/>
      <inertia ixx="1.0" ixy="0.0" ixz="0.0" iyy="1.0" iyz="0.0" izz="1.0"/>
    </inertial>
  </link>
  <joint name="ultrasonic_joint" type="fixed">
    <parent link="base_link"/>
    <child link="ultrasonic"/>
    <origin rpy="0 0 0" xyz="0 -0.0833211 0.0501713"/>
  </joint>
  <transmission name="tran1">
    <type>transmission_interface/SimpleTransmission</type>
    <joint name="left_wheel_joint">
      <hardwareInterface>hardware_interface/VelocityJointInterface</hardwareInterface>
    </joint>
    <actuator name="left_motor">
      <hardwareInterface>hardware_interface/VelocityJointInterface</hardwareInterface>
      <mechanicalReduction>1</mechanicalReduction>
    </actuator>
  </transmission>
  <transmission name="tran2">
    <type>transmission_interface/SimpleTransmission</type>
    <joint name="right_wheel_joint">
      <hardwareInterface>hardware_interface/VelocityJointInterface</hardwareInterface>
    </joint>
    <actuator name="right_motor">
      <hardwareInterface>hardware_interface/VelocityJointInterface</hardwareInterface>
      <mechanicalReduction>1</mechanicalReduction>
    </actuator>
  </transmission>
  <transmission name="tran3">
    <type>transmission_interface/SimpleTransmission</type>
    <joint name="arm_joint">
      <hardwareInterface>hardware_interface/VelocityJointInterface</hardwareInterface>
    </joint>
    <actuator name="arm_motor">
      <hardwareInterface>hardware_interface/VelocityJointInterface</hardwareInterface>
      <mechanicalReduction>1</mechanicalReduction>
    </actuator>
  </transmission>
  <transmission name="tran4">
    <type>transmission_interface/SimpleTransmission</type>
    <joint name="tail_joint">
      <hardwareInterface>hardware_interface/VelocityJointInterface</hardwareInterface>
    </joint>
    <actuator name="tail_motor">
      <hardwareInterface>hardware_interface/VelocityJointInterface</hardwareInterface>
      <mechanicalReduction>1</mechanicalReduction>
    </actuator>
  </transmission>
  <gazebo reference="base_link">
    <selfCollide>true</selfCollide>
    <mu1 value="0.4"/>
    <mu2 value="0.4"/>
  </gazebo>
  <gazebo reference="arm">
    <selfCollide>true</selfCollide>
    <mu1 value="0.4"/>
    <mu2 value="0.4"/>
  </gazebo>
  <gazebo reference="tail">
    <selfCollide>true</selfCollide>
    <mu1 value="0.4"/>
    <mu2 value="0.4"/>
  </gazebo>
  <gazebo reference="right_wheel">
    <selfCollide>true</selfCollide>
    <mu1 value="0.8"/>
    <mu2 value="0.8"/>
  </gazebo>
  <gazebo reference="left_wheel">
    <selfCollide>true</selfCollide>
    <mu1 value="0.8"/>
    <mu2 value="0.8"/>
  </gazebo>
</robot>

