<?xml version="1.0"?>
<robot name="hackev" xmlns:xacro="http://www.ros.org/wiki/xacro">

  <xacro:property name="wheeldist" value="0.064" />
  <xacro:property name="package_name" value="hackev_description" />

  <xacro:macro name="default_inertial" params="mass">
    <inertial>
      <mass value="${mass}" />
      <inertia ixx="1.0" ixy="0.0" ixz="0.0" iyy="1.0" iyz="0.0" izz="1.0" />
    </inertial>
  </xacro:macro>

  <xacro:macro name="geometry_mesh" params="name">
    <visual>
      <geometry>
        <mesh filename="package://${package_name}/meshs/hackev_${name}.dae"/>
      </geometry>
    </visual>
    <collision>
      <geometry>
        <mesh filename="package://${package_name}/meshs/hackev_${name}.dae"/>
      </geometry>
    </collision>
  </xacro:macro>

  <xacro:macro name="gazebo_param" params="name mu1:=0.8 mu2:=0.8">
    <gazebo reference="${name}">
      <selfCollide>true</selfCollide>
      <mu1 value="${mu1}" />
      <mu2 value="${mu2}" />
    </gazebo>
  </xacro:macro>

  <gazebo>
    <plugin name="gazebo_ros_control" filename="libgazebo_ros_control.so">
      <robotNamespace>/hackev</robotNamespace>
    </plugin>
  </gazebo>

  <link name="base_link">
    <xacro:geometry_mesh name="body"/>
    <xacro:default_inertial mass="1.3"/>
  </link>

  <link name="odom"/>
  <joint name="dummy_joint" type="fixed">
    <parent link="odom"/>
    <child link="base_link"/>
  </joint>


  <xacro:macro name="wheel" params="suffix reflect turn">

    <link name="${suffix}_wheel">
      <visual>
        <origin xyz="0 0 0" rpy="0 ${turn*pi} 0" />
        <geometry>
          <mesh filename="package://hackev_description/meshs/hackev_wheel.dae"/>
        </geometry>
      </visual>
      <collision>
        <origin xyz="0 0 0" rpy="0 ${turn*pi} 0" />
        <geometry>
          <mesh filename="package://hackev_description/meshs/hackev_wheel.dae"/>
        </geometry>
      </collision>
      <xacro:default_inertial mass="0.1"/>
    </link>
    <joint name="${suffix}_wheel_joint" type="continuous">
      <axis xyz="1 0 0" rpy="0 0 0" />
      <parent link="base_link"/>
      <child link="${suffix}_wheel"/>
      <origin xyz="${reflect} 0.002875 -0.00231" rpy="0 0 0"/>
    </joint>

  </xacro:macro>

  <xacro:wheel suffix="left" reflect="${wheeldist}" turn="0"/>
  <xacro:wheel suffix="right" reflect="-${wheeldist}" turn="1"/>

  <link name="arm">
    <xacro:geometry_mesh name="arm"/>
    <xacro:default_inertial mass="0.1"/>
  </link>
  <joint name="arm_joint" type="continuous">
    <axis xyz="1 0 0" rpy="0 0 0" />
    <parent link="base_link"/>
    <child link="arm"/>
    <origin xyz="0 -0.02893 0.01283" rpy="0 0 0"/>
  </joint>

  <link name="color">
    <xacro:geometry_mesh name="color"/>
    <xacro:default_inertial mass="0.05"/>
  </link>
  <joint name="color_joint" type="fixed">
    <parent link="arm"/>
    <child link="color"/>
    <origin xyz="0 -0.02995 -0.02625" rpy="0 0 0"/>
  </joint>

  <link name="tail">
    <xacro:geometry_mesh name="tail"/>
    <xacro:default_inertial mass="0.2"/>
  </link>
  <joint name="tail_joint" type="continuous">
    <axis xyz="0 1 0" rpy="0 0 0" />
    <parent link="base_link"/>
    <child link="tail"/>
    <origin xyz="0 0.1517738 0.0114206" rpy="0.0785398 0 0"/>
  </joint>

  <link name="gyro">
    <xacro:geometry_mesh name="gyro"/>
    <xacro:default_inertial mass="0.05"/>
  </link>
  <joint name="gyro_joint" type="fixed">
    <parent link="base_link"/>
    <child link="gyro"/>
    <origin xyz="-0.048 0.0318875 0.0773275" rpy="0 0 0"/>
  </joint>

  <link name="touch">
    <xacro:geometry_mesh name="touch"/>
    <xacro:default_inertial mass="0.05"/>
  </link>
  <joint name="touch_joint" type="fixed">
    <parent link="base_link"/>
    <child link="touch"/>
    <origin xyz="0.048 0.0318875 0.0773275" rpy="0 0 0"/>
  </joint>

  <link name="ultrasonic">
    <xacro:geometry_mesh name="ultrasonic"/>
    <xacro:default_inertial mass="0.05"/>
  </link>
  <joint name="ultrasonic_joint" type="fixed">
    <parent link="base_link"/>
    <child link="ultrasonic"/>
    <origin xyz="0 -0.0833211 0.0501713" rpy="0 0 0"/>
  </joint>

  <transmission name="tran1">
    <type>transmission_interface/SimpleTransmission</type>
    <joint name="left_wheel_joint">
      <hardwareInterface>hardware_interface/VelocityJointInterface</hardwareInterface>
    </joint>
    <actuator name="left_motor">
      <hardwareInterface>hardware_interface/VelocityJointInterface</hardwareInterface>
      <mechanicalReduction>1</mechanicalReduction>
    </actuator>
  </transmission>

  <transmission name="tran2">
    <type>transmission_interface/SimpleTransmission</type>
    <joint name="right_wheel_joint">
      <hardwareInterface>hardware_interface/VelocityJointInterface</hardwareInterface>
    </joint>
    <actuator name="right_motor">
      <hardwareInterface>hardware_interface/VelocityJointInterface</hardwareInterface>
      <mechanicalReduction>1</mechanicalReduction>
    </actuator>
  </transmission>

  <transmission name="tran3">
    <type>transmission_interface/SimpleTransmission</type>
    <joint name="arm_joint">
      <hardwareInterface>hardware_interface/VelocityJointInterface</hardwareInterface>
    </joint>
    <actuator name="arm_motor">
      <hardwareInterface>hardware_interface/VelocityJointInterface</hardwareInterface>
      <mechanicalReduction>1</mechanicalReduction>
    </actuator>
  </transmission>

  <transmission name="tran4">
    <type>transmission_interface/SimpleTransmission</type>
    <joint name="tail_joint">
      <hardwareInterface>hardware_interface/VelocityJointInterface</hardwareInterface>
    </joint>
    <actuator name="tail_motor">
      <hardwareInterface>hardware_interface/VelocityJointInterface</hardwareInterface>
      <mechanicalReduction>1</mechanicalReduction>
    </actuator>
  </transmission>
  <xacro:gazebo_param name="base_link" mu1="0.4" mu2="0.4"/>
  <xacro:gazebo_param name="arm" mu1="0.4" mu2="0.4"/>
  <xacro:gazebo_param name="tail" mu1="0.4" mu2="0.4"/>
  <xacro:gazebo_param name="right_wheel" mu1="0.8" mu2="0.8"/>
  <xacro:gazebo_param name="left_wheel" mu1="0.8" mu2="0.8"/>
</robot>
